2020-06-24T16:56:42|CRITICAL|root|Unhandled exception:Traceback (most recent call last):
  File "C:\Users\GingerLab\.julia\conda\3\envs\scopefoundry\lib\site-packages\ScopeFoundry\hardware.py", line 181, in read_from_hardware
    lq.read_from_hardware()
  File "C:\Users\GingerLab\.julia\conda\3\envs\scopefoundry\lib\site-packages\ScopeFoundry\logged_quantity.py", line 161, in read_from_hardware
    val = self.hardware_read_func()
  File "..\keithley_sourcemeter\keithley_sourcemeter_hc.py", line 63, in <lambda>
    self.V_a.connect_to_hardware(lambda:K.read_V(),None)
  File "..\keithley_sourcemeter\keithley_sourcemeter_gpib_interface.py", line 102, in read_V
    resp = self.ask(":READ?")
  File "..\keithley_sourcemeter\keithley_sourcemeter_gpib_interface.py", line 33, in ask
    resp = self.keithley.read()
  File "C:\Users\GingerLab\.julia\conda\3\envs\scopefoundry\lib\site-packages\pyvisa\resources\messagebased.py", line 427, in read
    message = self._read_raw().decode(enco)
UnicodeDecodeError: 'ascii' codec can't decode byte 0xcc in position 3: ordinal not in range(128)

