2020-06-22T15:16:46|WARNING|pymeasure.adapters.vxi11|Failed to import vxi11 package, which is required for the VXI11Adapter
2020-06-22T15:16:58|CRITICAL|root|Unhandled exception:Traceback (most recent call last):
  File "C:\Users\GingerLab\.julia\conda\3\envs\scopefoundry\lib\site-packages\ScopeFoundry\hardware.py", line 208, in enable_connection
    raise err
  File "C:\Users\GingerLab\.julia\conda\3\envs\scopefoundry\lib\site-packages\ScopeFoundry\hardware.py", line 204, in enable_connection
    self.connect()
  File "..\keithley_sourcemeter\keithley_sourcemeter_hc.py", line 61, in connect
    K = self.keithley = KeithleySourceMeter(port=self.port.val, debug=self.debug_mode.val)
  File "..\keithley_sourcemeter\keithley_sourcemeter_gpib_interface.py", line 28, in __init__
    self.keithley = Keithley2400(port)
  File "C:\Users\GingerLab\.julia\conda\3\envs\scopefoundry\lib\site-packages\pymeasure\instruments\keithley\keithley2400.py", line 307, in __init__
    super(Keithley2400, self).__init__(
  File "C:\Users\GingerLab\.julia\conda\3\envs\scopefoundry\lib\site-packages\pymeasure\instruments\instrument.py", line 52, in __init__
    adapter = VISAAdapter(adapter, **kwargs)
  File "C:\Users\GingerLab\.julia\conda\3\envs\scopefoundry\lib\site-packages\pymeasure\adapters\visa.py", line 65, in __init__
    self.connection = self.manager.get_instrument(
  File "C:\Users\GingerLab\.julia\conda\3\envs\scopefoundry\lib\site-packages\pyvisa\highlevel.py", line 1771, in open_resource
    res.open(access_mode, open_timeout)
  File "C:\Users\GingerLab\.julia\conda\3\envs\scopefoundry\lib\site-packages\pyvisa\resources\resource.py", line 218, in open
    self.session, status = self._resource_manager.open_bare_resource(self._resource_name, access_mode, open_timeout)
  File "C:\Users\GingerLab\.julia\conda\3\envs\scopefoundry\lib\site-packages\pyvisa\highlevel.py", line 1725, in open_bare_resource
    return self.visalib.open(self.session, resource_name, access_mode, open_timeout)
  File "C:\Users\GingerLab\.julia\conda\3\envs\scopefoundry\lib\site-packages\pyvisa\ctwrapper\functions.py", line 1213, in open
    ret = library.viOpen(session, resource_name, access_mode, open_timeout, byref(out_session))
  File "C:\Users\GingerLab\.julia\conda\3\envs\scopefoundry\lib\site-packages\pyvisa\ctwrapper\highlevel.py", line 193, in _return_handler
    raise errors.VisaIOError(ret_value)
pyvisa.errors.VisaIOError: VI_ERROR_RSRC_NFOUND (-1073807343): Insufficient location information or the requested device or resource is not present in the system.

2020-06-22T15:17:23|CRITICAL|root|Unhandled exception:Traceback (most recent call last):
  File "C:\Users\GingerLab\.julia\conda\3\envs\scopefoundry\lib\site-packages\ScopeFoundry\hardware.py", line 181, in read_from_hardware
    lq.read_from_hardware()
  File "C:\Users\GingerLab\.julia\conda\3\envs\scopefoundry\lib\site-packages\ScopeFoundry\logged_quantity.py", line 161, in read_from_hardware
    val = self.hardware_read_func()
  File "..\keithley_sourcemeter\keithley_sourcemeter_hc.py", line 64, in <lambda>
    self.V_a.connect_to_hardware(lambda:K.read_V(),None)
  File "..\keithley_sourcemeter\keithley_sourcemeter_gpib_interface.py", line 134, in read_V
    return self.keithley.voltage
  File "C:\Users\GingerLab\.julia\conda\3\envs\scopefoundry\lib\site-packages\pymeasure\instruments\instrument.py", line 216, in fget
    vals = self.values(command_process(get_command), **kwargs)
  File "C:\Users\GingerLab\.julia\conda\3\envs\scopefoundry\lib\site-packages\pymeasure\instruments\instrument.py", line 111, in values
    return self.adapter.values(command, **kwargs)
  File "C:\Users\GingerLab\.julia\conda\3\envs\scopefoundry\lib\site-packages\pymeasure\adapters\adapter.py", line 71, in values
    results = str(self.ask(command)).strip()
  File "C:\Users\GingerLab\.julia\conda\3\envs\scopefoundry\lib\site-packages\pymeasure\adapters\visa.py", line 112, in ask
    return self.connection.query(command)
  File "C:\Users\GingerLab\.julia\conda\3\envs\scopefoundry\lib\site-packages\pyvisa\resources\messagebased.py", line 613, in query
    return self.read()
  File "C:\Users\GingerLab\.julia\conda\3\envs\scopefoundry\lib\site-packages\pyvisa\resources\messagebased.py", line 427, in read
    message = self._read_raw().decode(enco)
  File "C:\Users\GingerLab\.julia\conda\3\envs\scopefoundry\lib\site-packages\pyvisa\resources\messagebased.py", line 400, in _read_raw
    chunk, status = self.visalib.read(self.session, size)
  File "C:\Users\GingerLab\.julia\conda\3\envs\scopefoundry\lib\site-packages\pyvisa\ctwrapper\functions.py", line 1584, in read
    ret = library.viRead(session, buffer, count, byref(return_count))
  File "C:\Users\GingerLab\.julia\conda\3\envs\scopefoundry\lib\site-packages\pyvisa\ctwrapper\highlevel.py", line 193, in _return_handler
    raise errors.VisaIOError(ret_value)
pyvisa.errors.VisaIOError: VI_ERROR_TMO (-1073807339): Timeout expired before operation completed.

2020-06-22T15:17:42|CRITICAL|root|Unhandled exception:Traceback (most recent call last):
  File "C:\Users\GingerLab\.julia\conda\3\envs\scopefoundry\lib\site-packages\ScopeFoundry\logged_quantity.py", line 241, in update_value
    self.hardware_set_func(self.val)
  File "..\keithley_sourcemeter\keithley_sourcemeter_hc.py", line 67, in <lambda>
    self.source_I_a.connect_to_hardware(None,lambda I:K.source_I(I))
  File "..\keithley_sourcemeter\keithley_sourcemeter_gpib_interface.py", line 60, in source_I
    self.keithley.source_current = I
  File "C:\Users\GingerLab\.julia\conda\3\envs\scopefoundry\lib\site-packages\pymeasure\instruments\instrument.py", line 181, in fset
    self.write(set_command % value)
  File "C:\Users\GingerLab\.julia\conda\3\envs\scopefoundry\lib\site-packages\pymeasure\instruments\instrument.py", line 99, in write
    self.adapter.write(command)
  File "C:\Users\GingerLab\.julia\conda\3\envs\scopefoundry\lib\site-packages\pymeasure\adapters\visa.py", line 86, in write
    self.connection.write(command)
  File "C:\Users\GingerLab\.julia\conda\3\envs\scopefoundry\lib\site-packages\pyvisa\resources\messagebased.py", line 228, in write
    count = self.write_raw(message.encode(enco))
  File "C:\Users\GingerLab\.julia\conda\3\envs\scopefoundry\lib\site-packages\pyvisa\resources\messagebased.py", line 202, in write_raw
    return self.visalib.write(self.session, message)
  File "C:\Users\GingerLab\.julia\conda\3\envs\scopefoundry\lib\site-packages\pyvisa\ctwrapper\functions.py", line 1866, in write
    ret = library.viWrite(session, data, len(data), byref(return_count))
  File "C:\Users\GingerLab\.julia\conda\3\envs\scopefoundry\lib\site-packages\pyvisa\ctwrapper\highlevel.py", line 193, in _return_handler
    raise errors.VisaIOError(ret_value)
pyvisa.errors.VisaIOError: VI_ERROR_TMO (-1073807339): Timeout expired before operation completed.

2020-06-22T15:20:48|ERROR|KeithleyTestApp|tried to disconnect keithley_sourcemeter: VI_ERROR_TMO (-1073807339): Timeout expired before operation completed.
