2020-06-26T13:00:47|CRITICAL|root|Unhandled exception:Traceback (most recent call last):
  File "C:\Users\GingerLab\.julia\conda\3\envs\scopefoundry\lib\site-packages\ScopeFoundry\hardware.py", line 204, in enable_connection
    self.connect()
  File "..\keithley_sourcemeter\keithley_sourcemeter_hc.py", line 60, in connect
    print(K.read_V())
  File "..\keithley_sourcemeter\keithley_sourcemeter_gpib_interface.py", line 122, in read_V
    resp = self.ask(":READ?")
  File "..\keithley_sourcemeter\keithley_sourcemeter_gpib_interface.py", line 45, in ask
    resp = self.keithley.query(cmd)
  File "C:\Users\GingerLab\.julia\conda\3\envs\scopefoundry\lib\site-packages\pyvisa\resources\messagebased.py", line 613, in query
    return self.read()
  File "C:\Users\GingerLab\.julia\conda\3\envs\scopefoundry\lib\site-packages\pyvisa\resources\messagebased.py", line 427, in read
    message = self._read_raw().decode(enco)
  File "C:\Users\GingerLab\.julia\conda\3\envs\scopefoundry\lib\site-packages\pyvisa\resources\messagebased.py", line 400, in _read_raw
    chunk, status = self.visalib.read(self.session, size)
  File "C:\Users\GingerLab\.julia\conda\3\envs\scopefoundry\lib\site-packages\pyvisa\ctwrapper\functions.py", line 1584, in read
    ret = library.viRead(session, buffer, count, byref(return_count))
  File "C:\Users\GingerLab\.julia\conda\3\envs\scopefoundry\lib\site-packages\pyvisa\ctwrapper\highlevel.py", line 193, in _return_handler
    raise errors.VisaIOError(ret_value)
pyvisa.errors.VisaIOError: VI_ERROR_TMO (-1073807339): Timeout expired before operation completed.

During handling of the above exception, another exception occurred:

Traceback (most recent call last):
  File "C:\Users\GingerLab\.julia\conda\3\envs\scopefoundry\lib\site-packages\ScopeFoundry\hardware.py", line 219, in enable_connection
    raise err
  File "C:\Users\GingerLab\.julia\conda\3\envs\scopefoundry\lib\site-packages\ScopeFoundry\hardware.py", line 212, in enable_connection
    self.disconnect()
  File "..\keithley_sourcemeter\keithley_sourcemeter_hc.py", line 100, in disconnect
    self.keithley.write_output_on(False)
  File "..\keithley_sourcemeter\keithley_sourcemeter_gpib_interface.py", line 113, in write_output_on
    self.send(s)
  File "..\keithley_sourcemeter\keithley_sourcemeter_gpib_interface.py", line 53, in send
    self.keithley.write(cmd)
  File "C:\Users\GingerLab\.julia\conda\3\envs\scopefoundry\lib\site-packages\pyvisa\resources\messagebased.py", line 228, in write
    count = self.write_raw(message.encode(enco))
  File "C:\Users\GingerLab\.julia\conda\3\envs\scopefoundry\lib\site-packages\pyvisa\resources\messagebased.py", line 202, in write_raw
    return self.visalib.write(self.session, message)
  File "C:\Users\GingerLab\.julia\conda\3\envs\scopefoundry\lib\site-packages\pyvisa\ctwrapper\functions.py", line 1866, in write
    ret = library.viWrite(session, data, len(data), byref(return_count))
  File "C:\Users\GingerLab\.julia\conda\3\envs\scopefoundry\lib\site-packages\pyvisa\ctwrapper\highlevel.py", line 193, in _return_handler
    raise errors.VisaIOError(ret_value)
pyvisa.errors.VisaIOError: VI_ERROR_TMO (-1073807339): Timeout expired before operation completed.

2020-06-26T13:00:47|CRITICAL|root|Unhandled exception:Traceback (most recent call last):
  File "C:\Users\GingerLab\.julia\conda\3\envs\scopefoundry\lib\site-packages\ScopeFoundry\hardware.py", line 208, in enable_connection
    raise err
  File "C:\Users\GingerLab\.julia\conda\3\envs\scopefoundry\lib\site-packages\ScopeFoundry\hardware.py", line 204, in enable_connection
    self.connect()
  File "..\keithley_sourcemeter\keithley_sourcemeter_hc.py", line 60, in connect
    print(K.read_V())
  File "..\keithley_sourcemeter\keithley_sourcemeter_gpib_interface.py", line 122, in read_V
    resp = self.ask(":READ?")
  File "..\keithley_sourcemeter\keithley_sourcemeter_gpib_interface.py", line 45, in ask
    resp = self.keithley.query(cmd)
  File "C:\Users\GingerLab\.julia\conda\3\envs\scopefoundry\lib\site-packages\pyvisa\resources\messagebased.py", line 613, in query
    return self.read()
  File "C:\Users\GingerLab\.julia\conda\3\envs\scopefoundry\lib\site-packages\pyvisa\resources\messagebased.py", line 427, in read
    message = self._read_raw().decode(enco)
  File "C:\Users\GingerLab\.julia\conda\3\envs\scopefoundry\lib\site-packages\pyvisa\resources\messagebased.py", line 400, in _read_raw
    chunk, status = self.visalib.read(self.session, size)
  File "C:\Users\GingerLab\.julia\conda\3\envs\scopefoundry\lib\site-packages\pyvisa\ctwrapper\functions.py", line 1584, in read
    ret = library.viRead(session, buffer, count, byref(return_count))
  File "C:\Users\GingerLab\.julia\conda\3\envs\scopefoundry\lib\site-packages\pyvisa\ctwrapper\highlevel.py", line 193, in _return_handler
    raise errors.VisaIOError(ret_value)
pyvisa.errors.VisaIOError: VI_ERROR_TMO (-1073807339): Timeout expired before operation completed.

