2020-06-25T10:47:20|CRITICAL|root|Unhandled exception:Traceback (most recent call last):
  File "C:\Users\GingerLab\.julia\conda\3\envs\scopefoundry\lib\site-packages\ScopeFoundry\hardware.py", line 208, in enable_connection
    raise err
  File "C:\Users\GingerLab\.julia\conda\3\envs\scopefoundry\lib\site-packages\ScopeFoundry\hardware.py", line 204, in enable_connection
    self.connect()
  File "..\keithley_sourcemeter\keithley_sourcemeter_hc.py", line 62, in connect
    print(K.ask(":SENS:CURR:RANG?"))
  File "..\keithley_sourcemeter\keithley_sourcemeter_gpib_interface.py", line 37, in ask
    return resp
NameError: name 'resp' is not defined

