2020-06-24T16:12:36|CRITICAL|root|Unhandled exception:Traceback (most recent call last):
  File "C:\Users\GingerLab\.julia\conda\3\envs\scopefoundry\lib\site-packages\ScopeFoundry\hardware.py", line 208, in enable_connection
    raise err
  File "C:\Users\GingerLab\.julia\conda\3\envs\scopefoundry\lib\site-packages\ScopeFoundry\hardware.py", line 204, in enable_connection
    self.connect()
  File "..\keithley_sourcemeter\keithley_sourcemeter_hc.py", line 60, in connect
    K = self.keithley = KeithleySourceMeter(port=self.port.val, debug=self.debug_mode.val)
  File "..\keithley_sourcemeter\keithley_sourcemeter_gpib_interface.py", line 28, in __init__
    self.keithley = resource_manager.open_resource(port)
NameError: name 'resource_manager' is not defined

