2020-06-24T11:12:55|WARNING|pymeasure.adapters.vxi11|Failed to import vxi11 package, which is required for the VXI11Adapter
2020-06-24T11:13:19|CRITICAL|root|Unhandled exception:Traceback (most recent call last):
  File "C:\Users\GingerLab\.julia\conda\3\envs\scopefoundry\lib\site-packages\ScopeFoundry\hardware.py", line 208, in enable_connection
    raise err
  File "C:\Users\GingerLab\.julia\conda\3\envs\scopefoundry\lib\site-packages\ScopeFoundry\hardware.py", line 204, in enable_connection
    self.connect()
  File "..\keithley_sourcemeter\keithley_sourcemeter_hc.py", line 58, in connect
    K = self.keithley = KeithleySourceMeter(port=self.port.val, debug=self.debug_mode.val)
  File "..\keithley_sourcemeter\keithley_sourcemeter_gpib_interface.py", line 26, in __init__
    self.keithley = Keithley2400(port)
  File "C:\Users\GingerLab\.julia\conda\3\envs\scopefoundry\lib\site-packages\pymeasure\instruments\keithley\keithley2400.py", line 307, in __init__
    super(Keithley2400, self).__init__(
  File "C:\Users\GingerLab\.julia\conda\3\envs\scopefoundry\lib\site-packages\pymeasure\instruments\instrument.py", line 52, in __init__
    adapter = VISAAdapter(adapter, **kwargs)
  File "C:\Users\GingerLab\.julia\conda\3\envs\scopefoundry\lib\site-packages\pymeasure\adapters\visa.py", line 65, in __init__
    self.connection = self.manager.get_instrument(
  File "C:\Users\GingerLab\.julia\conda\3\envs\scopefoundry\lib\site-packages\pyvisa\highlevel.py", line 1771, in open_resource
    res.open(access_mode, open_timeout)
  File "C:\Users\GingerLab\.julia\conda\3\envs\scopefoundry\lib\site-packages\pyvisa\resources\resource.py", line 230, in open
    self.clear()
  File "C:\Users\GingerLab\.julia\conda\3\envs\scopefoundry\lib\site-packages\pyvisa\resources\resource.py", line 287, in clear
    self.visalib.clear(self.session)
  File "C:\Users\GingerLab\.julia\conda\3\envs\scopefoundry\lib\site-packages\pyvisa\ctwrapper\functions.py", line 381, in clear
    return library.viClear(session)
  File "C:\Users\GingerLab\.julia\conda\3\envs\scopefoundry\lib\site-packages\pyvisa\ctwrapper\highlevel.py", line 193, in _return_handler
    raise errors.VisaIOError(ret_value)
pyvisa.errors.VisaIOError: VI_ERROR_TMO (-1073807339): Timeout expired before operation completed.

2020-06-24T11:13:47|CRITICAL|root|Unhandled exception:Traceback (most recent call last):
  File "C:\Users\GingerLab\.julia\conda\3\envs\scopefoundry\lib\site-packages\ScopeFoundry\hardware.py", line 208, in enable_connection
    raise err
  File "C:\Users\GingerLab\.julia\conda\3\envs\scopefoundry\lib\site-packages\ScopeFoundry\hardware.py", line 204, in enable_connection
    self.connect()
  File "..\keithley_sourcemeter\keithley_sourcemeter_hc.py", line 58, in connect
    K = self.keithley = KeithleySourceMeter(port=self.port.val, debug=self.debug_mode.val)
  File "..\keithley_sourcemeter\keithley_sourcemeter_gpib_interface.py", line 26, in __init__
    self.keithley = Keithley2400(port)
  File "C:\Users\GingerLab\.julia\conda\3\envs\scopefoundry\lib\site-packages\pymeasure\instruments\keithley\keithley2400.py", line 307, in __init__
    super(Keithley2400, self).__init__(
  File "C:\Users\GingerLab\.julia\conda\3\envs\scopefoundry\lib\site-packages\pymeasure\instruments\instrument.py", line 52, in __init__
    adapter = VISAAdapter(adapter, **kwargs)
  File "C:\Users\GingerLab\.julia\conda\3\envs\scopefoundry\lib\site-packages\pymeasure\adapters\visa.py", line 65, in __init__
    self.connection = self.manager.get_instrument(
  File "C:\Users\GingerLab\.julia\conda\3\envs\scopefoundry\lib\site-packages\pyvisa\highlevel.py", line 1771, in open_resource
    res.open(access_mode, open_timeout)
  File "C:\Users\GingerLab\.julia\conda\3\envs\scopefoundry\lib\site-packages\pyvisa\resources\resource.py", line 230, in open
    self.clear()
  File "C:\Users\GingerLab\.julia\conda\3\envs\scopefoundry\lib\site-packages\pyvisa\resources\resource.py", line 287, in clear
    self.visalib.clear(self.session)
  File "C:\Users\GingerLab\.julia\conda\3\envs\scopefoundry\lib\site-packages\pyvisa\ctwrapper\functions.py", line 381, in clear
    return library.viClear(session)
  File "C:\Users\GingerLab\.julia\conda\3\envs\scopefoundry\lib\site-packages\pyvisa\ctwrapper\highlevel.py", line 193, in _return_handler
    raise errors.VisaIOError(ret_value)
pyvisa.errors.VisaIOError: VI_ERROR_TMO (-1073807339): Timeout expired before operation completed.

2020-06-24T11:14:08|CRITICAL|root|Unhandled exception:Traceback (most recent call last):
  File "C:\Users\GingerLab\.julia\conda\3\envs\scopefoundry\lib\site-packages\ScopeFoundry\hardware.py", line 208, in enable_connection
    raise err
  File "C:\Users\GingerLab\.julia\conda\3\envs\scopefoundry\lib\site-packages\ScopeFoundry\hardware.py", line 204, in enable_connection
    self.connect()
  File "..\keithley_sourcemeter\keithley_sourcemeter_hc.py", line 58, in connect
    K = self.keithley = KeithleySourceMeter(port=self.port.val, debug=self.debug_mode.val)
  File "..\keithley_sourcemeter\keithley_sourcemeter_gpib_interface.py", line 26, in __init__
    self.keithley = Keithley2400(port)
  File "C:\Users\GingerLab\.julia\conda\3\envs\scopefoundry\lib\site-packages\pymeasure\instruments\keithley\keithley2400.py", line 307, in __init__
    super(Keithley2400, self).__init__(
  File "C:\Users\GingerLab\.julia\conda\3\envs\scopefoundry\lib\site-packages\pymeasure\instruments\instrument.py", line 52, in __init__
    adapter = VISAAdapter(adapter, **kwargs)
  File "C:\Users\GingerLab\.julia\conda\3\envs\scopefoundry\lib\site-packages\pymeasure\adapters\visa.py", line 65, in __init__
    self.connection = self.manager.get_instrument(
  File "C:\Users\GingerLab\.julia\conda\3\envs\scopefoundry\lib\site-packages\pyvisa\highlevel.py", line 1771, in open_resource
    res.open(access_mode, open_timeout)
  File "C:\Users\GingerLab\.julia\conda\3\envs\scopefoundry\lib\site-packages\pyvisa\resources\resource.py", line 230, in open
    self.clear()
  File "C:\Users\GingerLab\.julia\conda\3\envs\scopefoundry\lib\site-packages\pyvisa\resources\resource.py", line 287, in clear
    self.visalib.clear(self.session)
  File "C:\Users\GingerLab\.julia\conda\3\envs\scopefoundry\lib\site-packages\pyvisa\ctwrapper\functions.py", line 381, in clear
    return library.viClear(session)
  File "C:\Users\GingerLab\.julia\conda\3\envs\scopefoundry\lib\site-packages\pyvisa\ctwrapper\highlevel.py", line 193, in _return_handler
    raise errors.VisaIOError(ret_value)
pyvisa.errors.VisaIOError: VI_ERROR_TMO (-1073807339): Timeout expired before operation completed.

2020-06-24T11:14:31|CRITICAL|root|Unhandled exception:Traceback (most recent call last):
  File "C:\Users\GingerLab\.julia\conda\3\envs\scopefoundry\lib\site-packages\ScopeFoundry\hardware.py", line 208, in enable_connection
    raise err
  File "C:\Users\GingerLab\.julia\conda\3\envs\scopefoundry\lib\site-packages\ScopeFoundry\hardware.py", line 204, in enable_connection
    self.connect()
  File "..\keithley_sourcemeter\keithley_sourcemeter_hc.py", line 58, in connect
    K = self.keithley = KeithleySourceMeter(port=self.port.val, debug=self.debug_mode.val)
  File "..\keithley_sourcemeter\keithley_sourcemeter_gpib_interface.py", line 26, in __init__
    self.keithley = Keithley2400(port)
  File "C:\Users\GingerLab\.julia\conda\3\envs\scopefoundry\lib\site-packages\pymeasure\instruments\keithley\keithley2400.py", line 307, in __init__
    super(Keithley2400, self).__init__(
  File "C:\Users\GingerLab\.julia\conda\3\envs\scopefoundry\lib\site-packages\pymeasure\instruments\instrument.py", line 52, in __init__
    adapter = VISAAdapter(adapter, **kwargs)
  File "C:\Users\GingerLab\.julia\conda\3\envs\scopefoundry\lib\site-packages\pymeasure\adapters\visa.py", line 65, in __init__
    self.connection = self.manager.get_instrument(
  File "C:\Users\GingerLab\.julia\conda\3\envs\scopefoundry\lib\site-packages\pyvisa\highlevel.py", line 1771, in open_resource
    res.open(access_mode, open_timeout)
  File "C:\Users\GingerLab\.julia\conda\3\envs\scopefoundry\lib\site-packages\pyvisa\resources\resource.py", line 230, in open
    self.clear()
  File "C:\Users\GingerLab\.julia\conda\3\envs\scopefoundry\lib\site-packages\pyvisa\resources\resource.py", line 287, in clear
    self.visalib.clear(self.session)
  File "C:\Users\GingerLab\.julia\conda\3\envs\scopefoundry\lib\site-packages\pyvisa\ctwrapper\functions.py", line 381, in clear
    return library.viClear(session)
  File "C:\Users\GingerLab\.julia\conda\3\envs\scopefoundry\lib\site-packages\pyvisa\ctwrapper\highlevel.py", line 193, in _return_handler
    raise errors.VisaIOError(ret_value)
pyvisa.errors.VisaIOError: VI_ERROR_TMO (-1073807339): Timeout expired before operation completed.

