2020-06-23T12:44:17|WARNING|pymeasure.adapters.vxi11|Failed to import vxi11 package, which is required for the VXI11Adapter
2020-06-23T12:44:27|CRITICAL|root|Unhandled exception:Traceback (most recent call last):
  File "C:\Users\GingerLab\.julia\conda\3\envs\scopefoundry\lib\site-packages\ScopeFoundry\hardware.py", line 208, in enable_connection
    raise err
  File "C:\Users\GingerLab\.julia\conda\3\envs\scopefoundry\lib\site-packages\ScopeFoundry\hardware.py", line 204, in enable_connection
    self.connect()
  File "..\keithley_sourcemeter\keithley_sourcemeter_hc.py", line 77, in connect
    self.source_V_a_range.connect_to_hardware(self.read_range('source', 'v'),
  File "..\keithley_sourcemeter\keithley_sourcemeter_hc.py", line 124, in read_range
    return self.v_ranges_inv[_range]
KeyError: 0.21

