2020-06-23T15:10:58|WARNING|pymeasure.adapters.vxi11|Failed to import vxi11 package, which is required for the VXI11Adapter
2020-06-23T15:11:02|CRITICAL|root|Unhandled exception:Traceback (most recent call last):
  File "C:\Users\GingerLab\.julia\conda\3\envs\scopefoundry\lib\site-packages\ScopeFoundry\hardware.py", line 208, in enable_connection
    raise err
  File "C:\Users\GingerLab\.julia\conda\3\envs\scopefoundry\lib\site-packages\ScopeFoundry\hardware.py", line 204, in enable_connection
    self.connect()
  File "..\keithley_sourcemeter\keithley_sourcemeter_hc.py", line 93, in connect
    LQ['NPC_a'].hardware_read_func = K.read_NPLC
KeyError: 'NPC_a'

