2020-06-22T15:55:44|WARNING|pymeasure.adapters.vxi11|Failed to import vxi11 package, which is required for the VXI11Adapter
2020-06-22T15:56:03|CRITICAL|root|Unhandled exception:Traceback (most recent call last):
  File "C:\Users\GingerLab\.julia\conda\3\envs\scopefoundry\lib\site-packages\ScopeFoundry\hardware.py", line 208, in enable_connection
    raise err
  File "C:\Users\GingerLab\.julia\conda\3\envs\scopefoundry\lib\site-packages\ScopeFoundry\hardware.py", line 204, in enable_connection
    self.connect()
  File "..\keithley_sourcemeter\keithley_sourcemeter_hc.py", line 61, in connect
    K = self.keithley = KeithleySourceMeter(port=self.port.val, debug=self.debug_mode.val)
  File "..\keithley_sourcemeter\keithley_sourcemeter_gpib_interface.py", line 28, in __init__
    self.keithley = Keithley2400(port)
  File "C:\Users\GingerLab\.julia\conda\3\envs\scopefoundry\lib\site-packages\pymeasure\instruments\keithley\keithley2400.py", line 307, in __init__
    super(Keithley2400, self).__init__(
  File "C:\Users\GingerLab\.julia\conda\3\envs\scopefoundry\lib\site-packages\pymeasure\instruments\instrument.py", line 52, in __init__
    adapter = VISAAdapter(adapter, **kwargs)
  File "C:\Users\GingerLab\.julia\conda\3\envs\scopefoundry\lib\site-packages\pymeasure\adapters\visa.py", line 65, in __init__
    self.connection = self.manager.get_instrument(
  File "C:\Users\GingerLab\.julia\conda\3\envs\scopefoundry\lib\site-packages\pyvisa\highlevel.py", line 1750, in open_resource
    info = self.resource_info(resource_name, extended=True)
  File "C:\Users\GingerLab\.julia\conda\3\envs\scopefoundry\lib\site-packages\pyvisa\highlevel.py", line 1704, in resource_info
    ret, err = self.visalib.parse_resource_extended(self.session, resource_name)
  File "C:\Users\GingerLab\.julia\conda\3\envs\scopefoundry\lib\site-packages\pyvisa\ctwrapper\functions.py", line 1380, in parse_resource_extended
    ret = library.viParseRsrcEx(session, resource_name, byref(interface_type),
  File "C:\Users\GingerLab\.julia\conda\3\envs\scopefoundry\lib\site-packages\pyvisa\ctwrapper\highlevel.py", line 193, in _return_handler
    raise errors.VisaIOError(ret_value)
pyvisa.errors.VisaIOError: VI_ERROR_RSRC_NFOUND (-1073807343): Insufficient location information or the requested device or resource is not present in the system.

